Workbook

Sheet Kontrol Listesi
A1: COP31 SAĞLIK PAVILION (YEŞİL ALAN) HAZIRLIK KONTROL LİSTESİ
A2: T.C. Sağlık Bakanlığı Sağlığın Geliştirmesi Genel Müdürlüğü (SGGM) — COP31 Antalya, 9-20 Kasım 2026
A3: Hazırlık Başlangıcı: | C3: 17.09.2026 | D3: COP31 Etkinlik Tarihleri: | F3: 09.11.2026 - 20.11.2026 (Antalya) | G3: COP31'e Kalan Gün: | I3: =DATE(2026,11,9)-TODAY() -> 51
A4: Not: Yeşil Alan Başvuru Çağrısı'nın son başvuru tarihi 27 Eylül 2026'dır (cop31.saglik.gov.tr). 9 Kasım 2026 Sağlık Günü (Health Day) 10,11 Kasım SayınCumhurbaşkanına özel, Sağlık Pavilyonu programının odak günleridir.
A5: Not: 'Tamamlanma %' ve 'Kalan Gün' sütunları Durum ve Bitiş Tarihi'ne göre otomatik hesaplanır.
A7: No | B7: İş Paketi | C7: Faaliyet | D7: Açıklama / Detay | E7: Başlangıç Tarihi | F7: Bitiş Tarihi | G7: Sorumlu Birim | H7: Sorumlu Kişi | I7: Durum | J7: Tamamlanma % | K7: Kalan Gün | L7: Gecikme / Risk | M7: Öncelik | N7: Notlar
A8: 1 | B8: Genel Koordinasyon | C8: Proje yönetim ekibi ve görev dağılımının kurulması | D8: SGGM bünyesinde Pavilion Proje Sorumlusu ve alt ekiplerin (içerik, lojistik, iletişim, protokol) belirlenmesi | E8: 46282 | F8: 46289 | G8: SGGM Genel Müdürlüğü | I8: Başlanmadı | J8: =IF(I8="Tamamlandı",1,IF(I8="Devam Ediyor",0.5,IF(I8="Gecikti",0.25,0))) -> 0 | K8: =F8-TODAY() -> 5 | L8: =IF(OR(I8="Tamamlandı",I8="İptal"),"",IF(K8<0,"GECİKME RİSKİ",IF(K8<=7,"YAKLAŞIYOR",""))) -> YAKLAŞIYOR | M8: Yüksek | N8: Görevlendirme yazısı hazırlanacak
A9: 2 | B9: Genel Koordinasyon | C9: Sağlık Bakanlığı üst yönetimi ile kapsam çalışmaları | D9: Sağlık Bakanlığı ilgili genel müdürlükler ile koordinasyon toplantısı | E9: 46282 | F9: 46295 | G9: SGGM / Bakanlık Makamı | I9: Devam Ediyor | J9: =IF(I9="Tamamlandı",1,IF(I9="Devam Ediyor",0.5,IF(I9="Gecikti",0.25,0))) -> 0.5 | K9: =F9-TODAY() -> 11 | L9: =IF(OR(I9="Tamamlandı",I9="İptal"),"",IF(K9<0,"GECİKME RİSKİ",IF(K9<=7,"YAKLAŞIYOR",""))) | M9: Yüksek
A10: 3 | B10: Genel Koordinasyon | C10: İş takvimi ve haftalık koordinasyon toplantı planının oluşturulması | D10: Tüm alt ekiplerin katılacağı haftalık ilerleme toplantılarının takviminin çıkarılması | E10: 46282 | F10: 46290 | G10: SGGM Proje Sorumlusu | I10: Devam Ediyor | J10: =IF(I10="Tamamlandı",1,IF(I10="Devam Ediyor",0.5,IF(I10="Gecikti",0.25,0))) -> 0.5 | K10: =F10-TODAY() -> 6 | L10: =IF(OR(I10="Tamamlandı",I10="İptal"),"",IF(K10<0,"GECİKME RİSKİ",IF(K10<=7,"YAKLAŞIYOR",""))) -> YAKLAŞIYOR | M10: Orta
A11: 4 | B11: Genel Koordinasyon | C11: Dış paydaşlarla koordinasyon protokolünün kurulması | D11: COP31 Ulusal Organizasyon Komitesi ile irtibat noktalarının netleştirilmesi | E11: 46282 | F11: 46296 | G11: SGGM / Dış İlişkiler | H11: ÇEŞ | I11: Devam Ediyor | J11: =IF(I11="Tamamlandı",1,IF(I11="Devam Ediyor",0.5,IF(I11="Gecikti",0.25,0))) -> 0.5 | K11: =F11-TODAY() -> 12 | L11: =IF(OR(I11="Tamamlandı",I11="İptal"),"",IF(K11<0,"GECİKME RİSKİ",IF(K11<=7,"YAKLAŞIYOR",""))) | M11: Yüksek
A12: 5 | B12: Genel Koordinasyon | C12: Risk yönetimi ve acil durum planının hazırlanması | D12: Kurulum, etkinlik ve söküm süreçlerine ilişkin risk kayıt defteri ve aksiyon planı | E12: 46296 | F12: 46315 | G12: SGGM Proje Sorumlusu | I12: Başlanmadı | J12: =IF(I12="Tamamlandı",1,IF(I12="Devam Ediyor",0.5,IF(I12="Gecikti",0.25,0))) -> 0 | K12: =F12-TODAY() -> 31 | L12: =IF(OR(I12="Tamamlandı",I12="İptal"),"",IF(K12<0,"GECİKME RİSKİ",IF(K12<=7,"YAKLAŞIYOR",""))) | M12: Orta
A13: 6 | B13: Başvuru / Çağrı Süreci | C13: cop31.saglik.gov.tr üzerindeki 'Yeşil Alan Başvuru Çağrısı' metninin ve kılavuzunun hazırlanması | D13: Başvuru rehberi (PDF) ve form içeriğinin ekip içinde değerlendirilmesi | E13: 46268 | F13: 46271 | G13: SGGM İçerik Ekibi | I13: Tamamlandı | J13: =IF(I13="Tamamlandı",1,IF(I13="Devam Ediyor",0.5,IF(I13="Gecikti",0.25,0))) -> 1 | K13: =F13-TODAY() -> -13 | L13: =IF(OR(I13="Tamamlandı",I13="İptal"),"",IF(K13<0,"GECİKME RİSKİ",IF(K13<=7,"YAKLAŞIYOR",""))) | M13: Yüksek | N13: sggm@saglik.gov.tr ile teyit
A14: 7 | B14: Başvuru / Çağrı Süreci | C14: Son başvuru tarihinin ve değerlendirme takviminin teyit edilmesi | D14: Google Forms başvuru bağlantısı üzerinden güncel son tarihin doğrulanması | E14: 46268 | F14: 46271 | G14: SGGM İçerik Ekibi | I14: Tamamlandı | J14: =IF(I14="Tamamlandı",1,IF(I14="Devam Ediyor",0.5,IF(I14="Gecikti",0.25,0))) -> 1 | K14: =F14-TODAY() -> -13 | L14: =IF(OR(I14="Tamamlandı",I14="İptal"),"",IF(K14<0,"GECİKME RİSKİ",IF(K14<=7,"YAKLAŞIYOR",""))) | M14: Yüksek | N14: Son başvuru tarihi 27.09.2026 olarak teyit edildi
A15: 8 | B15: Başvuru / Çağrı Süreci | C15: Kurum içi ve paydaş çağrısının duyurulması | D15: Üniversiteler, STK'lar, uluslararası kuruluşlar ve ilgili genel müdürlüklere çağrının iletilmesi | E15: 46279 | F15: 46289 | G15: SGGM İletişim Ekibi | I15: Tamamlandı | J15: =IF(I15="Tamamlandı",1,IF(I15="Devam Ediyor",0.5,IF(I15="Gecikti",0.25,0))) -> 1 | K15: =F15-TODAY() -> 5 | L15: =IF(OR(I15="Tamamlandı",I15="İptal"),"",IF(K15<0,"GECİKME RİSKİ",IF(K15<=7,"YAKLAŞIYOR",""))) | M15: Yüksek | N15: Son başvuru: 27.09.2026 — duyuru bu tarihten önce tamamlanmalı
A16: 9 | B16: Başvuru / Çağrı Süreci | C16: Başvuruların Yeşil Alan portalı/Google Forms üzerinden kabulünün son bulması | D16: 27 Eylül 2026 son başvuru tarihinde başvuru sisteminin kapatılması ve tüm başvuruların dışa aktarılması | E16: 46292 | F16: 46292 | G16: SGGM İçerik Ekibi | I16: Başlanmadı | J16: =IF(I16="Tamamlandı",1,IF(I16="Devam Ediyor",0.5,IF(I16="Gecikti",0.25,0))) -> 0 | K16: =F16-TODAY() -> 8 | L16: =IF(OR(I16="Tamamlandı",I16="İptal"),"",IF(K16<0,"GECİKME RİSKİ",IF(K16<=7,"YAKLAŞIYOR",""))) | M16: Yüksek | N16: Kesin son tarih: 27.09.2026
A17: 10 | B17: Başvuru / Çağrı Süreci | C17: Gelen proje/etkinlik başvurularının toplanması ve ön değerlendirmesi | D17: Başvuruların (proje, araştırma, atölye, toplantı, iyi uygulama) kategorilere ayrılması | E17: 46293 | F17: 46303 | G17: SGGM Değerlendirme Komisyonu | I17: Başlanmadı | J17: =IF(I17="Tamamlandı",1,IF(I17="Devam Ediyor",0.5,IF(I17="Gecikti",0.25,0))) -> 0 | K17: =F17-TODAY() -> 19 | L17: =IF(OR(I17="Tamamlandı",I17="İptal"),"",IF(K17<0,"GECİKME RİSKİ",IF(K17<=7,"YAKLAŞIYOR",""))) | M17: Yüksek
A18: 11 | B18: Başvuru / Çağrı Süreci | C18: Kabul edilen içeriklerin başvuru sahiplerine bildirilmesi | D18: Onay/ret bildirimlerinin yapılması ve program taslağına yerleştirilmesi | E18: 46304 | F18: 46310 | G18: SGGM Değerlendirme Komisyonu | I18: Başlanmadı | J18: =IF(I18="Tamamlandı",1,IF(I18="Devam Ediyor",0.5,IF(I18="Gecikti",0.25,0))) -> 0 | K18: =F18-TODAY() -> 26 | L18: =IF(OR(I18="Tamamlandı",I18="İptal"),"",IF(K18<0,"GECİKME RİSKİ",IF(K18<=7,"YAKLAŞIYOR",""))) | M18: Orta
A19: 12 | B19: Konsept, Tasarım ve İçerik | C19: Pavilion teması ve mesajlarının belirlenmesi Pavilion konsepti: 'Sağlıklı İnsan, Sağlıklı Gezegen' görsel kimliğinin geliştirilmesi | D19: COP31 Sağlık Pavilionu ana temasıyla uyumlu mesaj çerçevesinin oluşturulması | E19: 46270 | F19: 46290 | G19: SGGM İçerik Ekibi | I19: Devam Ediyor | J19: =IF(I19="Tamamlandı",1,IF(I19="Devam Ediyor",0.5,IF(I19="Gecikti",0.25,0))) -> 0.5 | K19: =F19-TODAY() -> 6 | L19: =IF(OR(I19="Tamamlandı",I19="İptal"),"",IF(K19<0,"GECİKME RİSKİ",IF(K19<=7,"YAKLAŞIYOR",""))) -> YAKLAŞIYOR | M19: Yüksek | N19: WHO Health at COP31 teması referans alınacak
A20: 13 | B20: Konsept, Tasarım ve İçerik | C20: Stant/pavilion iç mimari ve görsel tasarım konseptinin hazırlanması | D20: Kurumsal kimlik, Bakanlık logosu ve COP31 görsel kimliğine uygun tasarım.Mimari yerleşim: sahne, oturma, deneyim alanı, stant, backstage ve depolama | E20: 46290 | F20: 46310 | G20: SGGM Tasarım Ekibi / Dış Tedarikçi | I20: Başlanmadı | J20: =IF(I20="Tamamlandı",1,IF(I20="Devam Ediyor",0.5,IF(I20="Gecikti",0.25,0))) -> 0 | K20: =F20-TODAY() -> 26 | L20: =IF(OR(I20="Tamamlandı",I20="İptal"),"",IF(K20<0,"GECİKME RİSKİ",IF(K20<=7,"YAKLAŞIYOR",""))) | M20: Yüksek
A21: 14 | B21: Konsept, Tasarım ve İçerik | C21: Stand/pano, infografik ve dijital içeriklerin hazırlanması | D21: Sağlık-iklim verilerini içeren pano, video ve interaktif ekran içeriklerinin üretimi | E21: 46296 | F21: 46320 | G21: SGGM İçerik Ekibi | I21: Başlanmadı | J21: =IF(I21="Tamamlandı",1,IF(I21="Devam Ediyor",0.5,IF(I21="Gecikti",0.25,0))) -> 0 | K21: =F21-TODAY() -> 36 | L21: =IF(OR(I21="Tamamlandı",I21="İptal"),"",IF(K21<0,"GECİKME RİSKİ",IF(K21<=7,"YAKLAŞIYOR",""))) | M21: Orta
A22: 15 | B22: Konsept, Tasarım ve İçerik | C22: Çok dilli (TR/EN) materyal ve çeviri sürecinin tamamlanması | D22: Broşür, sunum ve pano metinlerinin İngilizce çevirilerinin yaptırılması | E22: 46305 | F22: 46325 | G22: SGGM / Çeviri Birimi | I22: Başlanmadı | J22: =IF(I22="Tamamlandı",1,IF(I22="Devam Ediyor",0.5,IF(I22="Gecikti",0.25,0))) -> 0 | K22: =F22-TODAY() -> 41 | L22: =IF(OR(I22="Tamamlandı",I22="İptal"),"",IF(K22<0,"GECİKME RİSKİ",IF(K22<=7,"YAKLAŞIYOR",""))) | M22: Orta
A23: 16 | B23: Program ve Etkinlikler | C23: Pavilion 12 günlük etkinlik takviminin (9-20 Kasım) oluşturulması.Günlük dashboard ve yönetici özet formatının hazırlanması | D23: Her gün için panel, atölye ve yan etkinliklerin saat bazlı programlanması.Görevli iletişim listesi ve WhatsApp/acil iletişim grubunun kurulması | E23: 46304 | F23: 46327 | G23: SGGM Program Ekibi | I23: Başlanmadı | J23: =IF(I23="Tamamlandı",1,IF(I23="Devam Ediyor",0.5,IF(I23="Gecikti",0.25,0))) -> 0 | K23: =F23-TODAY() -> 43 | L23: =IF(OR(I23="Tamamlandı",I23="İptal"),"",IF(K23<0,"GECİKME RİSKİ",IF(K23<=7,"YAKLAŞIYOR",""))) | M23: Yüksek
A24: 17 | B24: Program ve Etkinlikler | C24: 9 Kasım Sağlık Günü (Health Day) ana programının netleştirilmesi | D24: Açılış konuşmaları, yüksek düzey panel ve basın toplantısının planlanması | E24: 46287 | F24: 46327 | G24: SGGM Program Ekibi | I24: Başlanmadı | J24: =IF(I24="Tamamlandı",1,IF(I24="Devam Ediyor",0.5,IF(I24="Gecikti",0.25,0))) -> 0 | K24: =F24-TODAY() -> 43 | L24: =IF(OR(I24="Tamamlandı",I24="İptal"),"",IF(K24<0,"GECİKME RİSKİ",IF(K24<=7,"YAKLAŞIYOR",""))) | M24: Yüksek | N24: COP31'in odak günlerinden biri
A25: 18 | B25: Program ve Etkinlikler | C25: 10 Kasım ATACH Day programının WHO/ATACH ile koordinasyonu | D25: İklim ve Sağlığa Dayanıklı Sağlık Sistemleri İttifakı (ATACH) ile ortak oturumların planlanması | E25: 46287 | F25: 46327 | G25: SGGM / WHO İrtibat | I25: Başlanmadı | J25: =IF(I25="Tamamlandı",1,IF(I25="Devam Ediyor",0.5,IF(I25="Gecikti",0.25,0))) -> 0 | K25: =F25-TODAY() -> 43 | L25: =IF(OR(I25="Tamamlandı",I25="İptal"),"",IF(K25<0,"GECİKME RİSKİ",IF(K25<=7,"YAKLAŞIYOR",""))) | M25: Yüksek
A26: 19 | B26: Program ve Etkinlikler | C26: Konuşmacı ve panelist davetlerinin gönderilmesi | D26: Ulusal/uluslararası uzman, akademisyen ve yetkililere davet ve teyit süreci | E26: 46296 | F26: 46315 | G26: SGGM Protokol Ekibi | I26: Başlanmadı | J26: =IF(I26="Tamamlandı",1,IF(I26="Devam Ediyor",0.5,IF(I26="Gecikti",0.25,0))) -> 0 | K26: =F26-TODAY() -> 31 | L26: =IF(OR(I26="Tamamlandı",I26="İptal"),"",IF(K26<0,"GECİKME RİSKİ",IF(K26<=7,"YAKLAŞIYOR",""))) | M26: Yüksek
A27: 20 | B27: Program ve Etkinlikler | C27: Moderatör brifingleri ve oturum akış planlarının hazırlanması.Her kritik risk için B planı ve sorumlu belirlenmesi | D27: Her oturum için moderatör notu, süre planı ve soru-cevap formatının belirlenmesi | E27: 46315 | F27: 46331 | G27: SGGM Program Ekibi | I27: Başlanmadı | J27: =IF(I27="Tamamlandı",1,IF(I27="Devam Ediyor",0.5,IF(I27="Gecikti",0.25,0))) -> 0 | K27: =F27-TODAY() -> 47 | L27: =IF(OR(I27="Tamamlandı",I27="İptal"),"",IF(K27<0,"GECİKME RİSKİ",IF(K27<=7,"YAKLAŞIYOR",""))) | M27: Düşük
A28: 21 | B28: Paydaş ve Protokol | C28: Health Pavilionda yer alacak dış katılımcılar ile koordinasyon toplantıları | D28: Pavilyon alanının metrekare, konum ve teknik altyapı,promosyan malzeme temini netleştirilmesi | E28: 46282 | F28: 46303 | G28: SGGM | I28: Başlanmadı | J28: =IF(I28="Tamamlandı",1,IF(I28="Devam Ediyor",0.5,IF(I28="Gecikti",0.25,0))) -> 0 | K28: =F28-TODAY() -> 19 | L28: =IF(OR(I28="Tamamlandı",I28="İptal"),"",IF(K28<0,"GECİKME RİSKİ",IF(K28<=7,"YAKLAŞIYOR",""))) | M28: Yüksek
A29: 22 | B29: Paydaş ve Protokol | C29: WHO, UNFCCC ve uluslararası sağlık kuruluşlarıyla işbirliği protokollerinin takibi | D29: Ortak etkinlik ve içerik üretimi için mutabakat metinlerinin hazırlanması | E29: 46280 | F29: 46327 | G29: SGGM / | H29: UA | I29: Devam Ediyor | J29: =IF(I29="Tamamlandı",1,IF(I29="Devam Ediyor",0.5,IF(I29="Gecikti",0.25,0))) -> 0.5 | K29: =F29-TODAY() -> 43 | L29: =IF(OR(I29="Tamamlandı",I29="İptal"),"",IF(K29<0,"GECİKME RİSKİ",IF(K29<=7,"YAKLAŞIYOR",""))) | M29: Orta
A30: 23 | B30: Paydaş ve Protokol | C30: VIP ve üst düzey ziyaretçi protokol planının hazırlanması | D30: Bakan, milletvekili ve yabancı heyet ziyaretleri için karşılama/güzergah planı | E30: 46310 | F30: 46331 | G30: SGGM Protokol Ekibi | I30: Başlanmadı | J30: =IF(I30="Tamamlandı",1,IF(I30="Devam Ediyor",0.5,IF(I30="Gecikti",0.25,0))) -> 0 | K30: =F30-TODAY() -> 47 | L30: =IF(OR(I30="Tamamlandı",I30="İptal"),"",IF(K30<0,"GECİKME RİSKİ",IF(K30<=7,"YAKLAŞIYOR",""))) | M30: Orta
A31: 24 | B31: Paydaş ve Protokol | C31: Akreditasyon ve giriş-çıkış izinlerinin (Bakanlık personeli, konuşmacılar) alınması | D31: saha akreditasyon sürecinin takibi ve personel listelerinin iletilmesi | E31: 46296 | F31: 46320 | G31: SGGM İnsan Kaynakları | I31: Başlanmadı | J31: =IF(I31="Tamamlandı",1,IF(I31="Devam Ediyor",0.5,IF(I31="Gecikti",0.25,0))) -> 0 | K31: =F31-TODAY() -> 36 | L31: =IF(OR(I31="Tamamlandı",I31="İptal"),"",IF(K31<0,"GECİKME RİSKİ",IF(K31<=7,"YAKLAŞIYOR",""))) | M31: Yüksek
A32: 25 | B32: Lojistik ve Saha Kurulumu | C32: Stant kurulum firması/yükleniciyle sözleşme ve teknik şartnamenin tamamlanması | D32: İhale/satınalma süreci sonrası kurulum takviminin netleştirilmesi | E32: 46290 | F32: 46315 | G32: SGGM Satınalma / Lojistik | I32: Başlanmadı | J32: =IF(I32="Tamamlandı",1,IF(I32="Devam Ediyor",0.5,IF(I32="Gecikti",0.25,0))) -> 0 | K32: =F32-TODAY() -> 31 | L32: =IF(OR(I32="Tamamlandı",I32="İptal"),"",IF(K32<0,"GECİKME RİSKİ",IF(K32<=7,"YAKLAŞIYOR",""))) | M32: Yüksek
A33: 26 | B33: Lojistik ve Saha Kurulumu | C33: Mobilya, donanım ve sarf malzeme listesinin çıkarılması ve temini | D33: Masa, sandalye, tanıtım standı, promosyon malzemeleri vb. temini | E33: 46300 | F33: 46327 | G33: SGGM Lojistik Ekibi | I33: Başlanmadı | J33: =IF(I33="Tamamlandı",1,IF(I33="Devam Ediyor",0.5,IF(I33="Gecikti",0.25,0))) -> 0 | K33: =F33-TODAY() -> 43 | L33: =IF(OR(I33="Tamamlandı",I33="İptal"),"",IF(K33<0,"GECİKME RİSKİ",IF(K33<=7,"YAKLAŞIYOR",""))) | M33: Orta
A34: 27 | B34: Lojistik ve Saha Kurulumu | C34: Ulaşım, konaklama ve saha nakliye organizasyonu | D34: Personel ve konuk konuşmacılar için Antalya ulaşım/konaklama planlaması.Otel–EXPO Center shuttle/transfer planının netleştirilmesi | E34: 46286 | F34: 46331 | G34: SGGM Lojistik Ekibi | I34: Başlanmadı | J34: =IF(I34="Tamamlandı",1,IF(I34="Devam Ediyor",0.5,IF(I34="Gecikti",0.25,0))) -> 0 | K34: =F34-TODAY() -> 47 | L34: =IF(OR(I34="Tamamlandı",I34="İptal"),"",IF(K34<0,"GECİKME RİSKİ",IF(K34<=7,"YAKLAŞIYOR",""))) | M34: Orta
A35: 28 | B35: Lojistik ve Saha Kurulumu | C35: Pavilion fiziki kurulumunun ve sıfır atık köyünün sahada teftişi | D35: Stant, sergi alanı ve oturum alanlarının saha teslim tarihine göre planlama,Antalya seyahat | E35: 46328 | F35: 46334 | G35: SGGM Lojistik Ekibi | I35: Başlanmadı | J35: =IF(I35="Tamamlandı",1,IF(I35="Devam Ediyor",0.5,IF(I35="Gecikti",0.25,0))) -> 0 | K35: =F35-TODAY() -> 50 | L35: =IF(OR(I35="Tamamlandı",I35="İptal"),"",IF(K35<0,"GECİKME RİSKİ",IF(K35<=7,"YAKLAŞIYOR",""))) | M35: Yüksek | N35: COP31 alan teslim tarihine bağlı
A36: 29 | B36: Lojistik ve Saha Kurulumu | C36: Kurulum sonrası saha kontrolü ve prova | D36: Açılıştan önce tüm alanın son kontrol listesiyle denetlenmesi | E36: 46334 | F36: 46335 | G36: SGGM Proje Sorumlusu | I36: Başlanmadı | J36: =IF(I36="Tamamlandı",1,IF(I36="Devam Ediyor",0.5,IF(I36="Gecikti",0.25,0))) -> 0 | K36: =F36-TODAY() -> 51 | L36: =IF(OR(I36="Tamamlandı",I36="İptal"),"",IF(K36<0,"GECİKME RİSKİ",IF(K36<=7,"YAKLAŞIYOR",""))) | M36: Yüksek
A37: 30 | B37: Teknik Altyapı / AV | C37: Ses, görüntü, sahne kurulumu | D37: Panel alanları için AV ekipman temini | E37: 46305 | F37: 46333 | G37: SGGM Teknik Ekip / Yüklenici | I37: Başlanmadı | J37: =IF(I37="Tamamlandı",1,IF(I37="Devam Ediyor",0.5,IF(I37="Gecikti",0.25,0))) -> 0 | K37: =F37-TODAY() -> 49 | L37: =IF(OR(I37="Tamamlandı",I37="İptal"),"",IF(K37<0,"GECİKME RİSKİ",IF(K37<=7,"YAKLAŞIYOR",""))) | M37: Yüksek
A38: 31 | B38: Teknik Altyapı / AV | C38: İnternet, wifi ve canlı yayın altyapısının kurulması | D38: Oturumların çevrimiçi yayını için bant genişliği ve yayın altyapısının sağlanması | E38: 46310 | F38: 46333 | G38: SGGM Teknik Ekip | I38: Başlanmadı | J38: =IF(I38="Tamamlandı",1,IF(I38="Devam Ediyor",0.5,IF(I38="Gecikti",0.25,0))) -> 0 | K38: =F38-TODAY() -> 49 | L38: =IF(OR(I38="Tamamlandı",I38="İptal"),"",IF(K38<0,"GECİKME RİSKİ",IF(K38<=7,"YAKLAŞIYOR",""))) | M38: Orta
A39: 32 | B39: Teknik Altyapı / AV | C39: Dijital ekran ve interaktif sunum sistemlerinin test edilmesi | D39: Tüm dijital içeriklerin cihazlarda önceden test edilmesi | E39: 46327 | F39: 46334 | G39: SGGM Teknik Ekip | I39: Başlanmadı | J39: =IF(I39="Tamamlandı",1,IF(I39="Devam Ediyor",0.5,IF(I39="Gecikti",0.25,0))) -> 0 | K39: =F39-TODAY() -> 50 | L39: =IF(OR(I39="Tamamlandı",I39="İptal"),"",IF(K39<0,"GECİKME RİSKİ",IF(K39<=7,"YAKLAŞIYOR",""))) | M39: Orta
A40: 33 | B40: İletişim ve Tanıtım | C40: Pavilion iletişim ve medya stratejisinin hazırlanması | D40: Basın bülteni takvimi, sosyal medya planı ve görsel kimlik rehberinin oluşturulması | E40: 46287 | F40: 46305 | G40: SGGM İletişim Ekibi | I40: Başlanmadı | J40: =IF(I40="Tamamlandı",1,IF(I40="Devam Ediyor",0.5,IF(I40="Gecikti",0.25,0))) -> 0 | K40: =F40-TODAY() -> 21 | L40: =IF(OR(I40="Tamamlandı",I40="İptal"),"",IF(K40<0,"GECİKME RİSKİ",IF(K40<=7,"YAKLAŞIYOR",""))) | M40: Orta
A41: 34 | B41: İletişim ve Tanıtım | C41: Basın daveti ve akreditasyon listesinin hazırlanması | D41: Ulusal/uluslararası basın mensuplarının davet ve akreditasyon sürecinin yürütülmesi | E41: 46305 | F41: 46327 | G41: SGGM İletişim | I41: Başlanmadı | J41: =IF(I41="Tamamlandı",1,IF(I41="Devam Ediyor",0.5,IF(I41="Gecikti",0.25,0))) -> 0 | K41: =F41-TODAY() -> 43 | L41: =IF(OR(I41="Tamamlandı",I41="İptal"),"",IF(K41<0,"GECİKME RİSKİ",IF(K41<=7,"YAKLAŞIYOR",""))) | M41: Orta
...

Sheet Özet
A1: KONTROL LİSTESİ ÖZETİ
A3: Toplam Faaliyet | B3: =COUNTA('Kontrol Listesi'!C8:C60) -> 53
A4: Başlanmadı | B4: =COUNTIF('Kontrol Listesi'!I8:I60,"Başlanmadı") -> 44
A5: Devam Ediyor | B5: =COUNTIF('Kontrol Listesi'!I8:I60,"Devam Ediyor") -> 6
A6: Tamamlandı | B6: =COUNTIF('Kontrol Listesi'!I8:I60,"Tamamlandı") -> 3
A7: Gecikti | B7: =COUNTIF('Kontrol Listesi'!I8:I60,"Gecikti") -> 0
A8: İptal | B8: =COUNTIF('Kontrol Listesi'!I8:I60,"İptal") -> 0
A9: Ortalama Tamamlanma % | B9: =AVERAGE('Kontrol Listesi'!J8:J60) -> 0.11320755
A10: Gecikme Riski Taşıyan Faaliyet | B10: =COUNTIF('Kontrol Listesi'!L8:L60,"GECİKME RİSKİ") -> 0
A11: Son Tarihi Yaklaşan (≤7 gün) | B11: =COUNTIF('Kontrol Listesi'!L8:L60,"YAKLAŞIYOR") -> 3
A13: Tamamlanma Oranı (Faaliyet Bazında, %) | B13: =B6/B3 -> 0.056603774
A15: Kategori bazında faaliyet sayısı
A16: Kategori | B16: Faaliyet Sayısı
A17: Genel Koordinasyon | B17: =COUNTIF('Kontrol Listesi'!B8:B60,A17) -> 5
A18: Başvuru / Çağrı Süreci | B18: =COUNTIF('Kontrol Listesi'!B8:B60,A18) -> 6
A19: Konsept, Tasarım ve İçerik | B19: =COUNTIF('Kontrol Listesi'!B8:B60,A19) -> 4
A20: Program ve Etkinlikler | B20: =COUNTIF('Kontrol Listesi'!B8:B60,A20) -> 5
A21: Paydaş ve Protokol | B21: =COUNTIF('Kontrol Listesi'!B8:B60,A21) -> 4
A22: Lojistik ve Saha Kurulumu | B22: =COUNTIF('Kontrol Listesi'!B8:B60,A22) -> 5
A23: Teknik Altyapı / AV | B23: =COUNTIF('Kontrol Listesi'!B8:B60,A23) -> 3
A24: İletişim ve Tanıtım | B24: =COUNTIF('Kontrol Listesi'!B8:B60,A24) -> 4
A25: Bütçe ve Satınalma | B25: =COUNTIF('Kontrol Listesi'!B8:B60,A25) -> 3
A26: İnsan Kaynakları | B26: =COUNTIF('Kontrol Listesi'!B8:B60,A26) -> 3
A27: Güvenlik ve Sağlık Tedbirleri | B27: =COUNTIF('Kontrol Listesi'!B8:B60,A27) -> 3
A28: Saha Operasyonları (9-20 Kasım) | B28: =COUNTIF('Kontrol Listesi'!B8:B60,A28) -> 4
A29: Kapanış ve Raporlama | B29: =COUNTIF('Kontrol Listesi'!B8:B60,A29) -> 4
